<?xml version="1.0" ?>
<!-- =================================================================================== -->
<!-- |    This document was autogenerated by xacro from /home/harikrishnan/ROS_PROJECTS/snake_bot_ws/src/snake_bot/urdf/snake_robot.xacro | -->
<!-- |    EDITING THIS FILE BY HAND IS NOT RECOMMENDED                                 | -->
<!-- =================================================================================== -->
<robot name="snake_robot">
  <!-- Define Material for the robot -->
  <material name="blue">
    <color rgba="0 0 0.8 0.5"/>
  </material>
  <!-- Base Link Definition -->
  <link name="base_link">
    <visual>
      <origin rpy="3.14159 0 0" xyz="0 0.528 0"/>
      <geometry>
        <mesh filename="package://snake_bot/meshes/module.stl" scale="0.010 0.010 0.010"/>
      </geometry>
      <material name="blue"/>
    </visual>
    <collision>
      <geometry>
        <mesh filename="package://snake_bot/meshes/module.stl" scale="0.010 0.010 0.010"/>
      </geometry>
    </collision>
    <inertial>
      <mass value="1.0"/>
     <inertia ixx="0.1" ixy="0.05" ixz="0.05" iyy="0.1" iyz="0.05" izz="0.1"/>

    </inertial>
  </link>
  <gazebo reference="base_link">
    <material>Gazebo/Blue</material>
  </gazebo>
  <!-- Definition of Segments and Joints -->
  <link name="cross1">
    <visual>
      <origin rpy="0 0 0" xyz="0.065 -0.558 0.065"/>
      <geometry>
        <mesh filename="package://snake_bot/meshes/cross.stl" scale="0.010 0.010 0.010"/>
      </geometry>
      <material name="blue"/>
    </visual>
    <collision>
      <geometry>
        <mesh filename="package://snake_bot/meshes/cross.stl" scale="0.010 0.010 0.010"/>
      </geometry>
    </collision>
    <inertial>
      <mass value="1.0"/>
     <inertia ixx="0.1" ixy="0.05" ixz="0.05" iyy="0.1" iyz="0.05" izz="0.1"/>

    </inertial>
  </link>
  <gazebo reference="cross1">
    <material>Gazebo/Blue</material>
  </gazebo>
  <link name="segment1">
    <visual>
      <origin rpy="0 1.5708 0" xyz="0.0 -0.53 0"/>
      <geometry>
        <mesh filename="package://snake_bot/meshes/module.stl" scale="0.010 0.010 0.010"/>
      </geometry>
      <material name="blue"/>
    </visual>
    <collision>
      <geometry>
        <mesh filename="package://snake_bot/meshes/module.stl" scale="0.010 0.010 0.010"/>
      </geometry>
    </collision>
    <inertial>
      <mass value="1.0"/>
     <inertia ixx="0.1" ixy="0.05" ixz="0.05" iyy="0.1" iyz="0.05" izz="0.1"/>

    </inertial>
  </link>
  <gazebo reference="segment1">
    <material>Gazebo/Blue</material>
  </gazebo>
  <joint name="joint2" type="revolute">
    <parent link="base_link"/>
    <child link="cross1"/>
    <origin rpy="0 0 0" xyz="0 0 0"/>
    <axis xyz="1 0 0"/>
    <limit effort="100" lower="-1.57" upper="1.57" velocity="1"/>
  </joint>
  <joint name="joint1" type="revolute">
    <parent link="cross1"/>
    <child link="segment1"/>
    <origin rpy="0 0 0" xyz="0 0 0"/>
    <axis xyz="0 0 1"/>
    <limit effort="100" lower="-1.57" upper="1.57" velocity="1"/>
  </joint>
  <link name="segment2a">
    <visual>
      <origin rpy="0 0 3.14159" xyz="0.0 0  0"/>
      <geometry>
        <mesh filename="package://snake_bot/meshes/module.stl" scale="0.010 0.010 0.010"/>
      </geometry>
      <material name="blue"/>
    </visual>
    <collision>
      <geometry>
        <mesh filename="package://snake_bot/meshes/module.stl" scale="0.010 0.010 0.010"/>
      </geometry>
    </collision>
    <inertial>
      <mass value="1.0"/>
     <inertia ixx="0.1" ixy="0.05" ixz="0.05" iyy="0.1" iyz="0.05" izz="0.1"/>

    </inertial>
  </link>
  <gazebo reference="segment2a">
    <material>Gazebo/Blue</material>
  </gazebo>
  <joint name="joint_fix_mod_2" type="fixed">
    <parent link="segment1"/>
    <child link="segment2a"/>
    <origin rpy="0 0 0" xyz="0 -0.60 0"/>
  </joint>
  <link name="cross2">
    <visual>
      <origin rpy="0 0 0" xyz="0.065  -0.558  0.065"/>
      <geometry>
        <mesh filename="package://snake_bot/meshes/cross.stl" scale="0.010 0.010 0.010"/>
      </geometry>
      <material name="blue"/>
    </visual>
    <collision>
      <geometry>
        <mesh filename="package://snake_bot/meshes/cross.stl" scale="0.010 0.010 0.010"/>
      </geometry>
    </collision>
    <inertial>
      <mass value="1.0"/>
     <inertia ixx="0.1" ixy="0.05" ixz="0.05" iyy="0.1" iyz="0.05" izz="0.1"/>

    </inertial>
  </link>
  <gazebo reference="cross2">
    <material>Gazebo/Blue</material>
  </gazebo>
  <link name="segment2b">
    <visual>
      <origin rpy="0 1.5708 0" xyz="0.0 -0.558 0"/>
      <geometry>
        <mesh filename="package://snake_bot/meshes/module.stl" scale="0.010 0.010 0.010"/>
      </geometry>
      <material name="blue"/>
    </visual>
    <collision>
      <geometry>
        <mesh filename="package://snake_bot/meshes/module.stl" scale="0.010 0.010 0.010"/>
      </geometry>
    </collision>
    <inertial>
      <mass value="1.0"/>
     <inertia ixx="0.1" ixy="0.05" ixz="0.05" iyy="0.1" iyz="0.05" izz="0.1"/>

    </inertial>
  </link>
  <gazebo reference="segment2b">
    <material>Gazebo/Blue</material>
  </gazebo>
  <joint name="joint3" type="revolute">
    <parent link="cross2"/>
    <child link="segment2b"/>
    <origin rpy="0 0 0" xyz="0 0 0"/>
    <axis xyz="0 0 1"/>
    <limit effort="100" lower="-1.57" upper="1.57" velocity="1"/>
  </joint>
  <joint name="joint4" type="revolute">
    <parent link="segment2a"/>
    <child link="cross2"/>
    <origin rpy="0 0 0" xyz="0 -0.522  0"/>
    <axis xyz="1 0 0"/>
    <limit effort="100" lower="-1.57" upper="1.57" velocity="1"/>
  </joint>
  <link name="segment3a">
    <visual>
      <origin rpy="0 0 3.14159" xyz="0.0 0 0"/>
      <geometry>
        <mesh filename="package://snake_bot/meshes/module.stl" scale="0.010 0.010 0.010"/>
      </geometry>
      <material name="blue"/>
    </visual>
    <collision>
      <geometry>
        <mesh filename="package://snake_bot/meshes/module.stl" scale="0.010 0.010 0.010"/>
      </geometry>
    </collision>
    <inertial>
      <mass value="1.0"/>
     <inertia ixx="0.1" ixy="0.05" ixz="0.05" iyy="0.1" iyz="0.05" izz="0.1"/>

    </inertial>
  </link>
  <gazebo reference="segment3a">
    <material>Gazebo/Blue</material>
  </gazebo>
  <joint name="joint_fix_mod_3" type="fixed">
    <parent link="segment2b"/>
    <child link="segment3a"/>
    <origin rpy="0 0 0" xyz="0 -0.60 0"/>
  </joint>
  <link name="cross3">
    <visual>
      <origin rpy="0 0 0" xyz="0.065 -0.558 0.065"/>
      <geometry>
        <mesh filename="package://snake_bot/meshes/cross.stl" scale="0.010 0.010 0.010"/>
      </geometry>
      <material name="blue"/>
    </visual>
    <collision>
      <geometry>
        <mesh filename="package://snake_bot/meshes/cross.stl" scale="0.010 0.010 0.010"/>
      </geometry>
    </collision>
    <inertial>
      <mass value="1.0"/>
     <inertia ixx="0.1" ixy="0.05" ixz="0.05" iyy="0.1" iyz="0.05" izz="0.1"/>

    </inertial>
  </link>
  <gazebo reference="cross3">
    <material>Gazebo/Blue</material>
  </gazebo>
  <link name="segment3b">
    <visual>
      <origin rpy="0 1.5708 0" xyz="0.0 -0.558 0"/>
      <geometry>
        <mesh filename="package://snake_bot/meshes/module.stl" scale="0.010 0.010 0.010"/>
      </geometry>
      <material name="blue"/>
    </visual>
    <collision>
      <geometry>
        <mesh filename="package://snake_bot/meshes/module.stl" scale="0.010 0.010 0.010"/>
      </geometry>
    </collision>
    <inertial>
      <mass value="1.0"/>
     <inertia ixx="0.1" ixy="0.05" ixz="0.05" iyy="0.1" iyz="0.05" izz="0.1"/>

    </inertial>
  </link>
  <gazebo reference="segment3b">
    <material>Gazebo/Blue</material>
  </gazebo>
  <joint name="joint7" type="revolute">
    <parent link="cross3"/>
    <child link="segment3b"/>
    <origin rpy="0 0 0" xyz="0 0 0"/>
    <axis xyz="0 0 1"/>
    <limit effort="100" lower="-1.57" upper="1.57" velocity="1"/>
  </joint>
  <joint name="joint8" type="revolute">
    <parent link="segment3a"/>
    <child link="cross3"/>
    <origin rpy="0 0 0" xyz="0 -0.522 0"/>
    <axis xyz="1 0 0"/>
    <limit effort="100" lower="-1.57" upper="1.57" velocity="1"/>
  </joint>
  <link name="segment4a">
    <visual>
      <origin rpy="0 0 3.14159" xyz="0.0 0 0"/>
      <geometry>
        <mesh filename="package://snake_bot/meshes/module.stl" scale="0.010 0.010 0.010"/>
      </geometry>
      <material name="blue"/>
    </visual>
    <collision>
      <geometry>
        <mesh filename="package://snake_bot/meshes/module.stl" scale="0.010 0.010 0.010"/>
      </geometry>
    </collision>
    <inertial>
      <mass value="1.0"/>
     <inertia ixx="0.1" ixy="0.05" ixz="0.05" iyy="0.1" iyz="0.05" izz="0.1"/>

    </inertial>
  </link>
  <gazebo reference="segment4a">
    <material>Gazebo/Blue</material>
  </gazebo>
  <joint name="joint_fix_mod_4" type="fixed">
    <parent link="segment3b"/>
    <child link="segment4a"/>
    <origin rpy="0 0 0" xyz="0 -0.60 0"/>
  </joint>
  <link name="cross4">
    <visual>
      <origin rpy="0 0 0" xyz="0.065 -0.558 0.065"/>
      <geometry>
        <mesh filename="package://snake_bot/meshes/cross.stl" scale="0.010 0.010 0.010"/>
      </geometry>
      <material name="blue"/>
    </visual>
    <collision>
      <geometry>
        <mesh filename="package://snake_bot/meshes/cross.stl" scale="0.010 0.010 0.010"/>
      </geometry>
    </collision>
    <inertial>
      <mass value="1.0"/>
     <inertia ixx="0.1" ixy="0.05" ixz="0.05" iyy="0.1" iyz="0.05" izz="0.1"/>

    </inertial>
  </link>
  <gazebo reference="cross4">
    <material>Gazebo/Blue</material>
  </gazebo>
  <link name="segment4b">
    <visual>
      <origin rpy="0 1.5708 0" xyz="0.0 -0.558 0"/>
      <geometry>
        <mesh filename="package://snake_bot/meshes/module.stl" scale="0.010 0.010 0.010"/>
      </geometry>
      <material name="blue"/>
    </visual>
    <collision>
      <geometry>
        <mesh filename="package://snake_bot/meshes/module.stl" scale="0.010 0.010 0.010"/>
      </geometry>
    </collision>
    <inertial>
      <mass value="1.0"/>
     <inertia ixx="0.1" ixy="0.05" ixz="0.05" iyy="0.1" iyz="0.05" izz="0.1"/>

    </inertial>
  </link>
  <gazebo reference="segment4b">
    <material>Gazebo/Blue</material>
  </gazebo>
  <joint name="joint9" type="revolute">
    <parent link="cross4"/>
    <child link="segment4b"/>
    <origin rpy="0 0 0" xyz="0 0 0"/>
    <axis xyz="0 0 1"/>
    <limit effort="100" lower="-1.57" upper="1.57" velocity="1"/>
  </joint>
  <joint name="joint10" type="revolute">
    <parent link="segment4a"/>
    <child link="cross4"/>
    <origin rpy="0 0 0" xyz="0 -0.522 0"/>
    <axis xyz="1 0 0"/>
    <limit effort="100" lower="-1.57" upper="1.57" velocity="1"/>
  </joint>
  <link name="segment5a">
    <visual>
      <origin rpy="0 0 3.14159" xyz="0.0 0 0"/>
      <geometry>
        <mesh filename="package://snake_bot/meshes/module.stl" scale="0.010 0.010 0.010"/>
      </geometry>
      <material name="blue"/>
    </visual>
    <collision>
      <geometry>
        <mesh filename="package://snake_bot/meshes/module.stl" scale="0.010 0.010 0.010"/>
      </geometry>
    </collision>
    <inertial>
      <mass value="1.0"/>
     <inertia ixx="0.1" ixy="0.05" ixz="0.05" iyy="0.1" iyz="0.05" izz="0.1"/>

    </inertial>
  </link>
  <gazebo reference="segment5a">
    <material>Gazebo/Blue</material>
  </gazebo>
  <joint name="joint_fix_mod_5" type="fixed">
    <parent link="segment4b"/>
    <child link="segment5a"/>
    <origin rpy="0 0 0" xyz="0 -0.60 0"/>
  </joint>
  <link name="cross5">
    <visual>
      <origin rpy="0 0 0" xyz="0.065 -0.558 0.065"/>
      <geometry>
        <mesh filename="package://snake_bot/meshes/cross.stl" scale="0.010 0.010 0.010"/>
      </geometry>
      <material name="blue"/>
    </visual>
    <collision>
      <geometry>
        <mesh filename="package://snake_bot/meshes/cross.stl" scale="0.010 0.010 0.010"/>
      </geometry>
    </collision>
    <inertial>
      <mass value="1.0"/>
     <inertia ixx="0.1" ixy="0.05" ixz="0.05" iyy="0.1" iyz="0.05" izz="0.1"/>

    </inertial>
  </link>
  <gazebo reference="cross5">
    <material>Gazebo/Blue</material>
  </gazebo>
  <link name="segment5b">
    <visual>
      <origin rpy="0 1.5708 0" xyz="0.0 -0.558 0"/>
      <geometry>
        <mesh filename="package://snake_bot/meshes/module.stl" scale="0.010 0.010 0.010"/>
      </geometry>
      <material name="blue"/>
    </visual>
    <collision>
      <geometry>
        <mesh filename="package://snake_bot/meshes/module.stl" scale="0.010 0.010 0.010"/>
      </geometry>
    </collision>
    <inertial>
      <mass value="1.0"/>
     <inertia ixx="0.1" ixy="0.05" ixz="0.05" iyy="0.1" iyz="0.05" izz="0.1"/>

    </inertial>
  </link>
  <gazebo reference="segment5b">
    <material>Gazebo/Blue</material>
  </gazebo>
  <joint name="joint11" type="revolute">
    <parent link="cross5"/>
    <child link="segment5b"/>
    <origin rpy="0 0 0" xyz="0 0 0"/>
    <axis xyz="0 0 1"/>
    <limit effort="100" lower="-1.57" upper="1.57" velocity="1"/>
  </joint>
  <joint name="joint12" type="revolute">
    <parent link="segment5a"/>
    <child link="cross5"/>
    <origin rpy="0 0 0" xyz="0 -0.522 0"/>
    <axis xyz="1 0 0"/>
    <limit effort="100" lower="-1.57" upper="1.57" velocity="1"/>
  </joint>
  <link name="segment6a">
    <visual>
      <origin rpy="0 0 3.14159" xyz="0.0 0 0"/>
      <geometry>
        <mesh filename="package://snake_bot/meshes/module.stl" scale="0.010 0.010 0.010"/>
      </geometry>
      <material name="blue"/>
    </visual>
    <collision>
      <geometry>
        <mesh filename="package://snake_bot/meshes/module.stl" scale="0.010 0.010 0.010"/>
      </geometry>
    </collision>
    <inertial>
      <mass value="1.0"/>
     <inertia ixx="0.1" ixy="0.05" ixz="0.05" iyy="0.1" iyz="0.05" izz="0.1"/>

    </inertial>
  </link>
  <gazebo reference="segment6a">
    <material>Gazebo/Blue</material>
  </gazebo>
  <joint name="joint_fix_mod_6" type="fixed">
    <parent link="segment5b"/>
    <child link="segment6a"/>
    <origin rpy="0 0 0" xyz="0 -0.60 0"/>
  </joint>
  <link name="cross6">
    <visual>
      <origin rpy="0 0 0" xyz="0.065 -0.558 0.065"/>
      <geometry>
        <mesh filename="package://snake_bot/meshes/cross.stl" scale="0.010 0.010 0.010"/>
      </geometry>
      <material name="blue"/>
    </visual>
    <collision>
      <geometry>
        <mesh filename="package://snake_bot/meshes/cross.stl" scale="0.010 0.010 0.010"/>
      </geometry>
    </collision>
    <inertial>
      <mass value="1.0"/>
     <inertia ixx="0.1" ixy="0.05" ixz="0.05" iyy="0.1" iyz="0.05" izz="0.1"/>

    </inertial>
  </link>
  <gazebo reference="cross6">
    <material>Gazebo/Blue</material>
  </gazebo>
  <link name="segment6b">
    <visual>
      <origin rpy="0 1.5708 0" xyz="0.0 -0.558 0"/>
      <geometry>
        <mesh filename="package://snake_bot/meshes/module.stl" scale="0.010 0.010 0.010"/>
      </geometry>
      <material name="blue"/>
    </visual>
    <collision>
      <geometry>
        <mesh filename="package://snake_bot/meshes/module.stl" scale="0.010 0.010 0.010"/>
      </geometry>
    </collision>
    <inertial>
      <mass value="1.0"/>
     <inertia ixx="0.1" ixy="0.05" ixz="0.05" iyy="0.1" iyz="0.05" izz="0.1"/>

    </inertial>
  </link>
  <gazebo reference="segment6b">
    <material>Gazebo/Blue</material>
  </gazebo>
  <joint name="joint13" type="revolute">
    <parent link="cross6"/>
    <child link="segment6b"/>
    <origin rpy="0 0 0" xyz="0 0 0"/>
    <axis xyz="0 0 1"/>
    <limit effort="100" lower="-1.57" upper="1.57" velocity="1"/>
  </joint>
  <joint name="joint14" type="revolute">
    <parent link="segment6a"/>
    <child link="cross6"/>
    <origin rpy="0 0 0" xyz="0 -0.522 0"/>
    <axis xyz="1 0 0"/>
    <limit effort="100" lower="-1.57" upper="1.57" velocity="1"/>
  </joint>
  <!-- Gazebo plugin for joint control -->
  <gazebo>
    <plugin filename="libgazebo_ros_control.so" name="gazebo_ros_control">
      <robotNamespace>/snake_robot</robotNamespace>
    </plugin>
  </gazebo>

  <ros2_control name="SnakeRobotSystem" type="system">
  <hardware>
    <plugin>gazebo_ros2_control/GazeboSystem</plugin>
  </hardware>
  <joint name="joint1">
    <command_interface name="position">
      <param name="min">-1.57</param>
      <param name="max">1.57</param>
    </command_interface>
    <state_interface name="position"/>
    <state_interface name="velocity"/>
  </joint>
   <joint name="joint2">
    <command_interface name="position">
      <param name="min">-1.57</param>
      <param name="max">1.57</param>
    </command_interface>
    <state_interface name="position"/>
    <state_interface name="velocity"/>
  </joint>
   <joint name="joint3">
    <command_interface name="position">
      <param name="min">-1.57</param>
      <param name="max">1.57</param>
    </command_interface>
    <state_interface name="position"/>
    <state_interface name="velocity"/>
  </joint>
   <joint name="joint4">
    <command_interface name="position">
      <param name="min">-1.57</param>
      <param name="max">1.57</param>
    </command_interface>
    <state_interface name="position"/>
    <state_interface name="velocity"/>
  </joint>
   <joint name="joint5">
    <command_interface name="position">
      <param name="min">-1.57</param>
      <param name="max">1.57</param>
    </command_interface>
    <state_interface name="position"/>
    <state_interface name="velocity"/>
  </joint>
   <joint name="joint6">
    <command_interface name="position">
      <param name="min">-1.57</param>
      <param name="max">1.57</param>
    </command_interface>
    <state_interface name="position"/>
    <state_interface name="velocity"/>
  </joint>
   <joint name="joint7">
    <command_interface name="position">
      <param name="min">-1.57</param>
      <param name="max">1.57</param>
    </command_interface>
    <state_interface name="position"/>
    <state_interface name="velocity"/>
  </joint>
   <joint name="joint8">
    <command_interface name="position">
      <param name="min">-1.57</param>
      <param name="max">1.57</param>
    </command_interface>
    <state_interface name="position"/>
    <state_interface name="velocity"/>
  </joint>
   <joint name="joint9">
    <command_interface name="position">
      <param name="min">-1.57</param>
      <param name="max">1.57</param>
    </command_interface>
    <state_interface name="position"/>
    <state_interface name="velocity"/>
  </joint>
   <joint name="joint10">
    <command_interface name="position">
      <param name="min">-1.57</param>
      <param name="max">1.57</param>
    </command_interface>
    <state_interface name="position"/>
    <state_interface name="velocity"/>
  </joint> <joint name="joint11">
    <command_interface name="position">
      <param name="min">-1.57</param>
      <param name="max">1.57</param>
    </command_interface>
    <state_interface name="position"/>
    <state_interface name="velocity"/>
  </joint>
   <joint name="joint12">
    <command_interface name="position">
      <param name="min">-1.57</param>
      <param name="max">1.57</param>
    </command_interface>
    <state_interface name="position"/>
    <state_interface name="velocity"/>
  </joint>
   <joint name="joint13">
    <command_interface name="position">
      <param name="min">-1.57</param>
      <param name="max">1.57</param>
    </command_interface>
    <state_interface name="position"/>
    <state_interface name="velocity"/>
  </joint>
   <joint name="joint14">
    <command_interface name="position">
      <param name="min">-1.57</param>
      <param name="max">1.57</param>
    </command_interface>
    <state_interface name="position"/>
    <state_interface name="velocity"/>
  </joint>

  <!-- Repeat for all other joints (joint2, joint3, etc.) -->
</ros2_control>
</robot>
