<mujoco model="Snakebot">
  <compiler angle="radian" meshdir="/home/harikrishnan/ROS_PROJECTS/snake_robot_harmonic_ws/src/Snakebot/meshes/"/>

  <asset>
    <mesh name="base_link" file="base_link.STL"/>
    <mesh name="chintu_1" file="chintu_1.STL"/>
    <mesh name="danda_1" file="danda_1.STL"/>
    <mesh name="chintu_4" file="chintu_4.STL"/>
    <mesh name="top_base" file="top_base.STL"/>
    <mesh name="chintu_2" file="chintu_2.STL"/>
    <mesh name="danda_2" file="danda_2.STL"/>
    <mesh name="chintu_5" file="chintu_5.STL"/>
    <mesh name="chintu_3" file="chintu_3.STL"/>
    <mesh name="support_danda" file="support_danda.STL"/>
    <mesh name="chintu_6" file="chintu_6.STL"/>
  </asset>

  <worldbody>
    <body name="base_link" pos="0 0 0.1" >\
    <!-- <camera name="track" pos="0.846 0.916 -1.465" xyaxes="0.866 0.000 0.500 -0.171 0.940 0.296" mode="trackcom"/> -->
    <inertial pos="0 0 0" mass="2.5" diaginertia="0.1 0.1 0.1"/>
    <joint type="free"/>
    <geom type="mesh" contype="0" conaffinity="0" group="1" density="0" rgba="0.75294 0.75294 0.75294 1" mesh="base_link"/>
    <geom type="mesh" rgba="0.75294 0.75294 0.75294 1" mesh="base_link"/>

    <body name="chintu_1" pos="0.04 -0.017 -1.4731e-05" quat="0.499998 0.5 -0.5 0.500002">
      <inertial pos="5.2368e-08 0.0059135 0.00028384" quat="0.707096 0.00393411 0.00393411 0.707096" mass="0.0037139" diaginertia="2.6234e-07 1.5739e-07 1.5609e-07"/>
      <joint name="chintu_1_joint" pos="0 0 0" axis="0 -1 0"/>
      <geom type="mesh" contype="0" conaffinity="0" group="1" density="0" rgba="0.62745 0.62745 0.62745 1" mesh="chintu_1"/>
      <geom type="mesh" rgba="0.62745 0.62745 0.62745 1" mesh="chintu_1"/>
      <body name="danda_1" pos="0 0.005 0.0125" quat="0.707105 0 0 -0.707108">
        <inertial pos="-0.035021 0.015811 0.027514" quat="-0.000114703 0.866199 0.000304217 0.499699" mass="0.012018" diaginertia="1.5099e-05 1.2891e-05 2.653e-06"/>
        <joint name="danda_1_joint" pos="0 0 0" axis="0 -1 0.00018414"/>
        <geom type="mesh" contype="0" conaffinity="0" group="1" density="0" rgba="0.62745 0.62745 0.62745 1" mesh="danda_1"/>
        <geom type="mesh" rgba="0.62745 0.62745 0.62745 1" mesh="danda_1"/>
        <body name="chintu_4" pos="-0.07 1.0128e-05 0.055" quat="-3.67321e-06 0 0 1">
          <inertial pos="8.3751e-11 -2.236e-06 0.012143" mass="0.0029582" diaginertia="2.2252e-07 1.3682e-07 1.355e-07"/>
          <joint name="chintu_4_joint" pos="0 0 0" axis="0 -1 -0.00018414"/>
          <geom type="mesh" contype="0" conaffinity="0" group="1" density="0" rgba="0.62745 0.62745 0.62745 1" mesh="chintu_4"/>
          <geom type="mesh" rgba="0.62745 0.62745 0.62745 1" mesh="chintu_4"/>
          <body name="top_base" pos="0.005 0 0.0125" quat="0.707105 6.51034e-05 -6.51032e-05 0.707108">
            <site name="site_1_top_base" type="sphere" size="0.0025" pos="-0.035 0.04 0.0" rgba="1 0 0 1"/>
            <site name="site_2_top_base" type="sphere" size="0.0025" pos="0.0315 0.0725 0.0" rgba="0 1 0 1"/>
            <inertial pos="-0.0010694 0.043151 0.0083727" quat="0.486931 0.516272 -0.482342 0.513525" mass="0.10045" diaginertia="0.000104953 5.73202e-05 5.19341e-05"/>
            <joint name="top_base_joint" pos="0 0 0" axis="0 -1 0"/>
            <geom type="mesh" contype="0" conaffinity="0" group="1" density="0" rgba="0.62745 0.62745 0.62745 1" mesh="top_base"/>
            <geom type="mesh" rgba="0.62745 0.62745 0.62745 1" mesh="top_base"/>
          </body>
        </body>
      </body>
    </body>
    <body name="chintu_2" pos="0 -0.017 -0.04" quat="0.707105 0.707108 0 0">
      <inertial pos="-6.5746e-08 0.005 0.00035704" quat="0.707107 0 0 0.707107" mass="0.0029582" diaginertia="2.2252e-07 1.3682e-07 1.355e-07"/>
      <joint name="chintu_2_joint" pos="0 0 0" axis="0 -1 0"/>
      <geom type="mesh" contype="0" conaffinity="0" group="1" density="0" rgba="0.62745 0.62745 0.62745 1" mesh="chintu_2"/>
      <geom type="mesh" rgba="0.62745 0.62745 0.62745 1" mesh="chintu_2"/>
      <body name="danda_2" pos="0 0.005 0.0125" quat="0.707105 0 0 -0.707108">
        <inertial pos="-0.035021 0.015801 0.02752" quat="-0.000274262 0.866199 0.00021215 0.499699" mass="0.012018" diaginertia="1.5099e-05 1.289e-05 2.65299e-06"/>
        <joint name="danda_2_joint" pos="0 0 0" axis="0 -1 -0.00018414"/>
        <geom type="mesh" contype="0" conaffinity="0" group="1" density="0" rgba="0.62745 0.62745 0.62745 1" mesh="danda_2"/>
        <geom type="mesh" rgba="0.62745 0.62745 0.62745 1" mesh="danda_2"/>
        <body name="chintu_5" pos="-0.07 -1.0128e-05 0.055" quat="-3.67321e-06 0 0 1">
          <site name="site_chintu_5" type="sphere" size="0.0015" pos="0 0 0.0125" rgba="1 0 0 1"/>
          <inertial pos="0 2.236e-06 0.012143" mass="0.0029582" diaginertia="2.2252e-07 1.3682e-07 1.355e-07"/>
          <joint name="chintu_5_joint" pos="0 0 0" axis="0 -1 0.00018414"/>
          <geom type="mesh" contype="0" conaffinity="0" group="1" density="0" rgba="0.62745 0.62745 0.62745 1" mesh="chintu_5"/>
          <geom type="mesh" rgba="0.62745 0.62745 0.62745 1" mesh="chintu_5"/>
        </body>
      </body>
    </body>
    <body name="chintu_3" pos="-0.035355 -0.017 0.035355" quat="-0.270602 -0.270596 -0.653283 0.653279">
      <inertial pos="0 0 0" mass="0.0029582" diaginertia="2.2252e-07 1.3682e-07 1.355e-07"/>
      <joint name="chintu_3_joint" pos="0 0 0" axis="0 -1 0"/>
      <geom type="mesh" contype="0" conaffinity="0" group="1" density="0" rgba="1 1 1 1" mesh="chintu_3"/>
      <geom type="mesh" rgba="1 1 1 1" mesh="chintu_3"/>
      <body name="support_danda" pos="0 0.005 0.0125" quat="0.707105 0 0 -0.707108">
        <inertial pos="-0.045001 0.021828 0.0275" quat="-4.62074e-06 0.836519 1.40459e-06 0.547937" mass="0.014448" diaginertia="2.60759e-05 2.1824e-05 4.7952e-06"/>
        <joint name="support_danda_joint" pos="0 0 0" axis="0 -1 0"/>
        <geom type="mesh" contype="0" conaffinity="0" group="1" density="0" rgba="0.62745 0.62745 0.62745 1" mesh="support_danda"/>
        <geom type="mesh" rgba="0.62745 0.62745 0.62745 1" mesh="support_danda"/>
        <body name="chintu_6" pos="-0.09 0 0.055" quat="-3.67321e-06 0 0 1">
          <site name="site_chintu_6" type="sphere" size="0.0015" pos="0 0 0.0125" rgba="0 1 0 1"/>
          <inertial pos="-1.1844e-10 0 0.012143" mass="0.0029582" diaginertia="2.2252e-07 1.3682e-07 1.355e-07"/>
          <joint name="chintu_6_joint" pos="0 0 0" axis="0 -1 0"/>
          <geom type="mesh" contype="0" conaffinity="0" group="1" density="0" rgba="0.62745 0.62745 0.62745 1" mesh="chintu_6"/>
          <geom type="mesh" rgba="0.62745 0.62745 0.62745 1" mesh="chintu_6"/>
        </body>
      </body>
    </body>
    </body>
  </worldbody>

  <equality>
    <connect name="kinematic_link_1" active="true" site1="site_chintu_5" site2="site_1_top_base" solref=".02 1" solimp="90 95 0.1"/>
    <connect name="kinematic_link_2" active="true" site1="site_chintu_6" site2="site_2_top_base" solref=".02 1" solimp="90 95 0.1"/>
  </equality>

  <!-- <equality>
    <weld name="weld_pos_1" active="true" body1="chintu_5" body2="top_base" 
          solref=".02 1" solimp="9000 9500 1000"/>
    <joint name="joint_1" joint1="chintu_5_joint" joint2="top_base_joint" 
          polycoef="0 1 0 0 0" solref=".02 1" solimp="9 9.5 0.01"/>
    
    <weld name="weld_pos_2" active="true" body1="chintu_6" body2="top_base" 
          solref=".02 1" solimp="9000 9500 1000"/>
    <joint name="joint_2" joint1="chintu_6_joint" joint2="top_base_joint" 
          polycoef="0 1 0 0 0" solref=".02 1" solimp="9 9.5 0.01"/>
  </equality> -->

  <actuator>
    <!-- Actuators for all legs -->
    <position name="motor_1" joint="chintu_1_joint" gear="10" ctrlrange="-2.5 2.5" />
    <position name="motor_2" joint="chintu_5_joint" gear="1" ctrlrange="-1 1" />
  </actuator>

</mujoco>
