<mujoco model="Snakebot">
  <compiler angle="radian" meshdir="/home/harikrishnan/ROS_PROJECTS/snake_robot_harmonic_ws/src/Snakebot/meshes/"/>

  <asset>
    <mesh name="base_link" file="base_link.STL"/>
    <mesh name="chintu_1" file="chintu_1.STL"/>
    <mesh name="danda_1" file="danda_1.STL"/>
    <mesh name="chintu_4" file="chintu_4.STL"/>
    <mesh name="chintu_2" file="chintu_2.STL"/>
    <mesh name="danda_2" file="danda_2.STL"/>
    <mesh name="chintu_5" file="chintu_5.STL"/>
    <mesh name="top_base" file="top_base.STL"/>
    <mesh name="chintu_3" file="chintu_3.STL"/>
    <mesh name="support_danda" file="support_danda.STL"/>
    <mesh name="chintu_6" file="chintu_6.STL"/>
  </asset>

  <worldbody>
    <body name="base_link" pos="0 0 0.1" >
    <inertial pos="0 0 0" mass="2.5" diaginertia="0.1 0.1 0.1"/>
    <joint type="free"/>
    <!-- Visual mesh only (no collision) -->
    <geom type="mesh" contype="1" conaffinity="1" group="1" density="0" rgba="0.752941 0.752941 0.752941 1" mesh="base_link"/>
    <!-- Simplified collision geometry - capsule approximation -->
    <geom type="capsule" size="0.04 0.02" pos="0 0 0" rgba="0.752941 0.752941 0.752941 0" contype="0" conaffinity="0"/>
    <body name="chintu_1" pos="0.04 -0.017 -1.4731e-05" quat="0.499998 0.5 -0.5 0.500002">
      <inertial pos="5.23676e-08 0.00591355 0.000283844" quat="0.707096 0.00392812 0.00392812 0.707096" mass="0.00371393" diaginertia="2.62338e-07 1.57392e-07 1.5609e-07"/>
      <joint name="chintu_1_joint" pos="0 0 0" axis="0 -1 0"/>
      <!-- Visual mesh only (no collision) -->
      <geom type="mesh" contype="0" conaffinity="0" group="1" rgba="0.627451 0.627451 0.627451 1" mesh="chintu_1"/>
      <!-- No collision geometry for this part -->
      <body name="danda_1" pos="0 0.005 0.0125" quat="0.707105 0 0 -0.707108">
        <inertial pos="-0.0350209 0.0158107 0.0275138" quat="-0.000114745 0.866198 0.000304169 0.499701" mass="0.0120182" diaginertia="1.50991e-05 1.28905e-05 2.65306e-06"/>
        <joint name="danda_1_joint" pos="0 0 0" axis="0 -1 0.00018414"/>
        <!-- Visual mesh only (no collision) -->
        <geom type="mesh" contype="0" conaffinity="0" group="1" rgba="0.627451 0.627451 0.627451 1" mesh="danda_1"/>
        <!-- Simplified collision geometry - capsule approximation -->
        <geom type="capsule" size="0.01 0.035" pos="-0.035 0.015 0.0275" quat="0.707 0 0.707 0" rgba="0.627451 0.627451 0.627451 0" contype="0" conaffinity="0"/>
        <body name="chintu_4" pos="-0.07 1.0128e-05 0.055" quat="-3.67321e-06 0 0 1">
          <site name="site_chintu_4" type="sphere" size="0.0015" pos="0 0 0.0125" rgba="1 0 0 1"/>
          <inertial pos="8.37506e-11 -2.23599e-06 0.012143" mass="0.0029582" diaginertia="2.22521e-07 1.36818e-07 1.35501e-07"/>
          <joint name="chintu_4_joint" pos="0 0 0" axis="0 -1 -0.00018414"/>
          <!-- Visual mesh only (no collision) -->
          <geom type="mesh" contype="0" conaffinity="0" group="1" rgba="0.627451 0.627451 0.627451 1" mesh="chintu_4"/>
          <!-- No collision geometry for this part -->
        </body>
      </body>
    </body>
    <body name="chintu_2" pos="0 -0.017 -0.04" quat="0.707105 0.707108 0 0">
      <inertial pos="-6.5746e-08 0.005 0.00035704" quat="0.707107 0 0 0.707107" mass="0.0029582" diaginertia="2.2252e-07 1.3682e-07 1.355e-07"/>
      <joint name="chintu_2_joint" pos="0 0 0" axis="0 -1 0"/>
      <!-- Visual mesh only (no collision) -->
      <geom type="mesh" contype="0" conaffinity="0" group="1" rgba="0.62745 0.62745 0.62745 1" mesh="chintu_2"/>
      <!-- No collision geometry for this part -->
      <body name="danda_2" pos="0 0.005 0.0125" quat="0.707105 0 0 -0.707108">
        <inertial pos="-0.0350209 0.0158006 0.0275196" quat="-0.00027424 0.866198 0.000212159 0.499701" mass="0.0120182" diaginertia="1.50991e-05 1.28905e-05 2.65306e-06"/>
        <joint name="danda_2_joint" pos="0 0 0" axis="0 -1 -0.00018414"/>
        <!-- Visual mesh only (no collision) -->
        <geom type="mesh" contype="0" conaffinity="0" group="1" rgba="0.627451 0.627451 0.627451 1" mesh="danda_2"/>
        <!-- Simplified collision geometry - capsule approximation -->
        <geom type="capsule" size="0.01 0.035" pos="-0.035 0.015 0.0275" quat="0.707 0 0.707 0" rgba="0.627451 0.627451 0.627451 0" contype="0" conaffinity="0"/>
        <body name="chintu_5" pos="-0.07 -1.0128e-05 0.055" quat="-3.67321e-06 0 0 1">
          <inertial pos="0 2.236e-06 0.012143" mass="0.0029582" diaginertia="2.2252e-07 1.3682e-07 1.355e-07"/>
          <joint name="chintu_5_joint" pos="0 0 0" axis="0 -1 0.00018414"/>
          <!-- Visual mesh only (no collision) -->
          <geom type="mesh" contype="0" conaffinity="0" group="1" rgba="0.62745 0.62745 0.62745 1" mesh="chintu_5"/>
          <!-- No collision geometry for this part -->
          <body name="top_base" pos="-0.035 0.04 0.0125" quat="0 0 0 1">
            <inertial pos="-0.00316689 0.0389291 0.00837195" quat="-0.0188662 0.70606 0.0239272 0.707496" mass="0.100446" diaginertia="0.000104954 5.73207e-05 5.19343e-05"/>
            <site name="site_1_top_base" type="sphere" size="0.0015" pos="0.0 0.005 0.0" rgba="1 0 0 1"/>
            <site name="site_2_top_base" type="sphere" size="0.0025" pos="0.0315 0.0725 0.0" rgba="0 1 0 1"/>
            <site name="site_3_top_base" type="sphere" size="0.0015" pos="-0.035 0.04 0" rgba="0 1 1 1"/>
            <joint name="top_base_joint" pos="-0.035 0.04 0" axis="1 0 0"/>
            <!-- Visual mesh only (no collision) -->
            <geom type="mesh" contype="1" conaffinity="1" group="1" rgba="0.627451 0.627451 0.627451 1" mesh="top_base"/>
            <!-- Simplified collision geometry - box approximation -->
            <geom type="box" size="0.02 0.04 0.01" pos="0 0.04 0.01" rgba="0.627451 0.627451 0.627451 0" contype="0" conaffinity="0"/>
          </body>
        </body>
      </body>
    </body>
    <body name="chintu_3" pos="-0.035355 -0.017 0.035355" quat="-0.270602 -0.270596 -0.653283 0.653279">
      <inertial pos="0 0.005 0.000357044" quat="0.707107 0 0 0.707107" mass="0.0029582" diaginertia="2.22521e-07 1.36818e-07 1.35501e-07"/>
      <joint name="chintu_3_joint" pos="0 0 0" axis="0 -1 0"/>
      <!-- Visual mesh only (no collision) -->
      <geom type="mesh" contype="0" conaffinity="0" group="1" rgba="0.627451 0.627451 0.627451 1" mesh="chintu_3"/>
      <!-- No collision geometry for this part -->
      <body name="support_danda" pos="0 0.005 0.0125" quat="0.707105 0 0 -0.707108">
        <inertial pos="-0.0450011 0.0218276 0.0274999" quat="-4.62052e-06 0.836519 1.4047e-06 0.547938" mass="0.0144478" diaginertia="2.60758e-05 2.18241e-05 4.7952e-06"/>
        <joint name="support_danda_joint" pos="0 0 0" axis="0 -1 0"/>
        <!-- Visual mesh only (no collision) -->
        <geom type="mesh" contype="0" conaffinity="0" group="1" rgba="0.627451 0.627451 0.627451 1" mesh="support_danda"/>
        <!-- Simplified collision geometry - capsule approximation -->
        <geom type="capsule" size="0.01 0.045" pos="-0.045 0.02 0.0275" quat="0.707 0 0.707 0" rgba="0.627451 0.627451 0.627451 0" contype="0" conaffinity="0"/>
        <body name="chintu_6" pos="-0.09 0 0.055" quat="-3.67321e-06 0 0 1">
          <site name="site_chintu_6" type="sphere" size="0.0015" pos="0 0 0.0125" rgba="0 1 0 1"/>
          <inertial pos="-1.18443e-10 0 0.012143" mass="0.0029582" diaginertia="2.22521e-07 1.36818e-07 1.35501e-07"/>
          <joint name="chintu_6_joint" pos="0 0 0" axis="0 -1 0"/>
          <!-- Visual mesh only (no collision) -->
          <geom type="mesh" contype="0" conaffinity="0" group="1" rgba="0.627451 0.627451 0.627451 1" mesh="chintu_6"/>
          <!-- No collision geometry for this part -->
        </body>
      </body>
    </body>
    </body>
  </worldbody>

  <equality>
    <weld name="weld_pos_1" active="true" body1="chintu_4" body2="top_base" 
          solref=".02 1" solimp="9000 9500 1000"/>
    <joint name="joint_1" joint1="chintu_4_joint" joint2="top_base_joint" 
          polycoef="0 1 0 0 0" solref=".02 1" solimp="9 9.5 0.01"/>
    
    <weld name="weld_pos_2" active="true" body1="chintu_6" body2="top_base" 
          solref=".02 1" solimp="9000 9500 1000"/>
    <joint name="joint_2" joint1="chintu_6_joint" joint2="top_base_joint" 
          polycoef="0 1 0 0 0" solref=".02 1" solimp="9 9.5 0.01"/>
  </equality>

  <actuator>
    <!-- Actuators for all legs -->
    <position name="motor_1" joint="chintu_1_joint" gear="10" ctrlrange="-3.5 3.5" />
    <position name="motor_2" joint="top_base_joint" gear="10" ctrlrange="-3.5 3.5" />
  </actuator>
</mujoco>