<?xml version="1.0" encoding="utf-8"?>
<!-- This URDF was automatically created by SolidWorks to URDF Exporter! Originally created by Stephen Brawner (brawner@gmail.com) 
     Commit Version: 1.6.0-4-g7f85cfe  Build Version: 1.6.7995.38578
     For more information, please see http://wiki.ros.org/sw_urdf_exporter -->
<robot
  name="Snakebot">
  <mujoco>
    <compiler meshdir="/home/harikrishnan/ROS_PROJECTS/snake_robot_harmonic_ws/src/Snakebot/meshes/" balanceinertia="true" discardvisual="false"/>
  </mujoco>
  <link
    name="base_link">
    <inertial>
      <origin
        xyz="0.0010709 -0.0086275 0.0031506"
        rpy="0 0 0" />
      <mass
        value="0.10045" />
      <inertia
        ixx="5.7303E-05"
        ixy="-3.3729E-07"
        ixz="-3.2597E-07"
        iyy="0.00010495"
        iyz="1.0702E-07"
        izz="5.1954E-05" />
    </inertial>
    <visual>
      <origin
        xyz="0 0 0"
        rpy="0 0 0" />
      <geometry>
        <mesh
          filename="package://Snakebot/meshes/base_link.STL" />
      </geometry>
      <material
        name="">
        <color
          rgba="0.75294 0.75294 0.75294 1" />
      </material>
    </visual>
    <collision>
      <origin
        xyz="0 0 0"
        rpy="0 0 0" />
      <geometry>
        <mesh
          filename="package://Snakebot/meshes/base_link.STL" />
      </geometry>
    </collision>
  </link>
  <link
    name="chintu_1">
    <inertial>
      <origin
        xyz="5.2368E-08 0.0059135 0.00028384"
        rpy="0 0 0" />
      <mass
        value="0.0037139" />
      <inertia
        ixx="1.5739E-07"
        ixy="-3.3372E-21"
        ixz="-1.4468E-11"
        iyy="2.6234E-07"
        iyz="-4.8677E-13"
        izz="1.5609E-07" />
    </inertial>
    <visual>
      <origin
        xyz="0 0 0"
        rpy="0 0 0" />
      <geometry>
        <mesh
          filename="package://Snakebot/meshes/chintu_1.STL" />
      </geometry>
      <material
        name="">
        <color
          rgba="0.62745 0.62745 0.62745 1" />
      </material>
    </visual>
    <collision>
      <origin
        xyz="0 0 0"
        rpy="0 0 0" />
      <geometry>
        <mesh
          filename="package://Snakebot/meshes/chintu_1.STL" />
      </geometry>
    </collision>
  </link>
  <joint
    name="chintu_1_joint"
    type="continuous">
    <origin
      xyz="0.04 -0.017 -1.4731E-05"
      rpy="1.5708 -1.5708 0" />
    <parent
      link="base_link" />
    <child
      link="chintu_1" />
    <axis
      xyz="0 -1 0" />
  </joint>
  <link
    name="danda_1">
    <inertial>
      <origin
        xyz="-0.035021 0.015811 0.027514"
        rpy="0 0 0" />
      <mass
        value="0.012018" />
      <inertia
        ixx="5.772E-06"
        ixy="-3.9999E-09"
        ixz="5.3936E-06"
        iyy="1.2891E-05"
        iyz="3.3649E-09"
        izz="1.198E-05" />
    </inertial>
    <visual>
      <origin
        xyz="0 0 0"
        rpy="0 0 0" />
      <geometry>
        <mesh
          filename="package://Snakebot/meshes/danda_1.STL" />
      </geometry>
      <material
        name="">
        <color
          rgba="0.62745 0.62745 0.62745 1" />
      </material>
    </visual>
    <collision>
      <origin
        xyz="0 0 0"
        rpy="0 0 0" />
      <geometry>
        <mesh
          filename="package://Snakebot/meshes/danda_1.STL" />
      </geometry>
    </collision>
  </link>
  <joint
    name="danda_1_joint"
    type="continuous">
    <origin
      xyz="0 0.005 0.0125"
      rpy="0 0 -1.5708" />
    <parent
      link="chintu_1" />
    <child
      link="danda_1" />
    <axis
      xyz="0 -1 0.00018414" />
  </joint>
  <link
    name="chintu_4">
    <inertial>
      <origin
        xyz="8.3198E-11 -2.236E-06 0.012143"
        rpy="0 0 0" />
      <mass
        value="0.0029582" />
      <inertia
        ixx="2.2252E-07"
        ixy="1.0785E-18"
        ixz="-5.9621E-16"
        iyy="1.3682E-07"
        iyz="2.4255E-13"
        izz="1.355E-07" />
    </inertial>
    <visual>
      <origin
        xyz="0 0 0"
        rpy="0 0 0" />
      <geometry>
        <mesh
          filename="package://Snakebot/meshes/chintu_4.STL" />
      </geometry>
      <material
        name="">
        <color
          rgba="0.62745 0.62745 0.62745 1" />
      </material>
    </visual>
    <collision>
      <origin
        xyz="0 0 0"
        rpy="0 0 0" />
      <geometry>
        <mesh
          filename="package://Snakebot/meshes/chintu_4.STL" />
      </geometry>
    </collision>
  </link>
  <joint
    name="chintu_4_joint"
    type="continuous">
    <origin
      xyz="-0.07 1.0128E-05 0.055"
      rpy="0 0 3.1416" />
    <parent
      link="danda_1" />
    <child
      link="chintu_4" />
    <axis
      xyz="0 -1 -0.00018414" />
  </joint>
  <link
    name="chintu_2">
    <inertial>
      <origin
        xyz="-6.57457866967692E-08 0.00499999999999961 0.000357044441884634"
        rpy="0 0 0" />
      <mass
        value="0.0029582016460902" />
      <inertia
        ixx="1.36818359770935E-07"
        ixy="-3.31364828560109E-21"
        ixz="2.42554327586436E-13"
        iyy="2.22521136002339E-07"
        iyz="-5.62570706283534E-21"
        izz="1.35501124662558E-07" />
    </inertial>
    <visual>
      <origin
        xyz="0 0 0"
        rpy="0 0 0" />
      <geometry>
        <mesh
          filename="package://Snakebot/meshes/chintu_2.STL" />
      </geometry>
      <material
        name="">
        <color
          rgba="0.627450980392157 0.627450980392157 0.627450980392157 1" />
      </material>
    </visual>
    <collision>
      <origin
        xyz="0 0 0"
        rpy="0 0 0" />
      <geometry>
        <mesh
          filename="package://Snakebot/meshes/chintu_2.STL" />
      </geometry>
    </collision>
  </link>
  <joint
    name="chintu_2_joint"
    type="continuous">
    <origin
      xyz="0 -0.017 -0.04"
      rpy="1.5708 0 0" />
    <parent
      link="base_link" />
    <child
      link="chintu_2" />
    <axis
      xyz="0 -1 0" />
  </joint>
  <link
    name="danda_2">
    <inertial>
      <origin
        xyz="-0.0350208855791254 0.0158005686441155 0.0275196223017284"
        rpy="0 0 0" />
      <mass
        value="0.0120182093602401" />
      <inertia
        ixx="5.77201812790807E-06"
        ixy="-5.98620448042408E-09"
        ixz="5.3935929231683E-06"
        iyy="1.28904992994651E-05"
        iyz="3.70010752068554E-09"
        izz="1.19801788446448E-05" />
    </inertial>
    <visual>
      <origin
        xyz="0 0 0"
        rpy="0 0 0" />
      <geometry>
        <mesh
          filename="package://Snakebot/meshes/danda_2.STL" />
      </geometry>
      <material
        name="">
        <color
          rgba="0.627450980392157 0.627450980392157 0.627450980392157 1" />
      </material>
    </visual>
    <collision>
      <origin
        xyz="0 0 0"
        rpy="0 0 0" />
      <geometry>
        <mesh
          filename="package://Snakebot/meshes/danda_2.STL" />
      </geometry>
    </collision>
  </link>
  <joint
    name="danda_2_joint"
    type="continuous">
    <origin
      xyz="0 0.005 0.0125"
      rpy="0 0 -1.5708" />
    <parent
      link="chintu_2" />
    <child
      link="danda_2" />
    <axis
      xyz="0 -1 -0.00018414" />
  </joint>
  <link
    name="chintu_5">
    <inertial>
      <origin
        xyz="-5.83887105332082E-13 2.23599110292516E-06 0.0121429553462325"
        rpy="0 0 0" />
      <mass
        value="0.0029582016460902" />
      <inertia
        ixx="2.22521136002339E-07"
        ixy="-2.75733789318083E-21"
        ixz="3.6091646622237E-18"
        iyy="1.36818359770935E-07"
        iyz="-2.42554327478381E-13"
        izz="1.35501124662558E-07" />
    </inertial>
    <visual>
      <origin
        xyz="0 0 0"
        rpy="0 0 0" />
      <geometry>
        <mesh
          filename="package://Snakebot/meshes/chintu_5.STL" />
      </geometry>
      <material
        name="">
        <color
          rgba="0.627450980392157 0.627450980392157 0.627450980392157 1" />
      </material>
    </visual>
    <collision>
      <origin
        xyz="0 0 0"
        rpy="0 0 0" />
      <geometry>
        <mesh
          filename="package://Snakebot/meshes/chintu_5.STL" />
      </geometry>
    </collision>
  </link>
  <joint
    name="chintu_5_joint"
    type="continuous">
    <origin
      xyz="-0.07 -1.0128E-05 0.055"
      rpy="0 0 3.1416" />
    <parent
      link="danda_2" />
    <child
      link="chintu_5" />
    <axis
      xyz="0 -1 0.00018414" />
  </joint>
  <link
    name="top_base">
    <inertial>
      <origin
        xyz="-0.00316689147367792 0.0389290744316808 0.00837195247826529"
        rpy="0 0 0" />
      <mass
        value="0.100445715067213" />
      <inertia
        ixx="5.19542502833525E-05"
        ixy="-3.2602918389402E-07"
        ixz="-1.16778734192659E-07"
        iyy="5.73033705373593E-05"
        iyz="3.37234331143521E-07"
        izz="0.000104951001037545" />
    </inertial>
    <visual>
      <origin
        xyz="0 0 0"
        rpy="0 0 0" />
      <geometry>
        <mesh
          filename="package://Snakebot/meshes/top_base.STL" />
      </geometry>
      <material
        name="">
        <color
          rgba="0.627450980392157 0.627450980392157 0.627450980392157 1" />
      </material>
    </visual>
    <collision>
      <origin
        xyz="0 0 0"
        rpy="0 0 0" />
      <geometry>
        <mesh
          filename="package://Snakebot/meshes/top_base.STL" />
      </geometry>
    </collision>
  </link>
  <joint
    name="top_base_joint"
    type="continuous">
    <origin
      xyz="0.005 0 0.0125"
      rpy="0 0.00018414 1.5708" />
    <parent
      link="chintu_5" />
    <child
      link="top_base" />
    <axis
      xyz="0 -1 0" />
  </joint>
  <link
    name="chintu_3">
    <inertial>
      <origin
        xyz="3.42365025218783E-14 0.00499999999999979 0.000357044448023671"
        rpy="0 0 0" />
      <mass
        value="0.0029582016460902" />
      <inertia
        ixx="1.36818359815598E-07"
        ixy="-3.02417231949387E-21"
        ixz="2.12353328817015E-22"
        iyy="2.22521136002339E-07"
        iyz="5.67218408090456E-21"
        izz="1.35501124617894E-07" />
    </inertial>
    <visual>
      <origin
        xyz="0 0 0"
        rpy="0 0 0" />
      <geometry>
        <mesh
          filename="package://Snakebot/meshes/chintu_3.STL" />
      </geometry>
      <material
        name="">
        <color
          rgba="0.627450980392157 0.627450980392157 0.627450980392157 1" />
      </material>
    </visual>
    <collision>
      <origin
        xyz="0 0 0"
        rpy="0 0 0" />
      <geometry>
        <mesh
          filename="package://Snakebot/meshes/chintu_3.STL" />
      </geometry>
    </collision>
  </link>
  <joint
    name="chintu_3_joint"
    type="continuous">
    <origin
      xyz="-0.035355 -0.017 0.035355"
      rpy="-1.5708 0.7854 3.1416" />
    <parent
      link="base_link" />
    <child
      link="chintu_3" />
    <axis
      xyz="0 -1 0" />
  </joint>
  <link
    name="support_danda">
    <inertial>
      <origin
        xyz="-0.0450011254970855 0.021827633136558 0.0274998502258311"
        rpy="0 0 0" />
      <mass
        value="0.0144478154829601" />
      <inertia
        ixx="8.19207289449909E-06"
        ixy="-1.49315456079876E-10"
        ixz="7.79415057647111E-06"
        iyy="2.18240706940893E-05"
        iyz="5.24904762280818E-11"
        izz="2.26789349667317E-05" />
    </inertial>
    <visual>
      <origin
        xyz="0 0 0"
        rpy="0 0 0" />
      <geometry>
        <mesh
          filename="package://Snakebot/meshes/support_danda.STL" />
      </geometry>
      <material
        name="">
        <color
          rgba="0.627450980392157 0.627450980392157 0.627450980392157 1" />
      </material>
    </visual>
    <collision>
      <origin
        xyz="0 0 0"
        rpy="0 0 0" />
      <geometry>
        <mesh
          filename="package://Snakebot/meshes/support_danda.STL" />
      </geometry>
    </collision>
  </link>
  <joint
    name="support_danda_joint"
    type="continuous">
    <origin
      xyz="0 0.005 0.0125"
      rpy="0 0 -1.5708" />
    <parent
      link="chintu_3" />
    <child
      link="support_danda" />
    <axis
      xyz="0 -1 0" />
  </joint>
  <link
    name="chintu_6">
    <inertial>
      <origin
        xyz="-1.19014978428034E-10 -2.52083076635046E-13 0.0121429555516021"
        rpy="0 0 0" />
      <mass
        value="0.0029582016460902" />
      <inertia
        ixx="2.2252113600234E-07"
        ixy="-1.30832841381797E-18"
        ixz="8.53478232691967E-16"
        iyy="1.36818359815598E-07"
        iyz="3.48467883140843E-20"
        izz="1.35501124617894E-07" />
    </inertial>
    <visual>
      <origin
        xyz="0 0 0"
        rpy="0 0 0" />
      <geometry>
        <mesh
          filename="package://Snakebot/meshes/chintu_6.STL" />
      </geometry>
      <material
        name="">
        <color
          rgba="0.627450980392157 0.627450980392157 0.627450980392157 1" />
      </material>
    </visual>
    <collision>
      <origin
        xyz="0 0 0"
        rpy="0 0 0" />
      <geometry>
        <mesh
          filename="package://Snakebot/meshes/chintu_6.STL" />
      </geometry>
    </collision>
  </link>
  <joint
    name="chintu_6_joint"
    type="continuous">
    <origin
      xyz="-0.09 0 0.055"
      rpy="0 0 -3.1416" />
    <parent
      link="support_danda" />
    <child
      link="chintu_6" />
    <axis
      xyz="0 -1 0" />
  </joint>
</robot>