<?xml version="1.0" encoding="utf-8"?>
<!-- This URDF was automatically created by SolidWorks to URDF Exporter! Originally created by Stephen Brawner (brawner@gmail.com) 
     Commit Version: 1.6.0-4-g7f85cfe  Build Version: 1.6.7995.38578
     For more information, please see http://wiki.ros.org/sw_urdf_exporter -->
<robot
  name="Snakebot">
  <link
    name="base_link">
    <inertial>
      <origin
        xyz="0.0010709 -0.0086275 0.0031506"
        rpy="0 0 0" />
      <mass
        value="0.10045" />
      <inertia
        ixx="5.7303E-05"
        ixy="-3.3729E-07"
        ixz="-3.2597E-07"
        iyy="0.00010495"
        iyz="1.0702E-07"
        izz="5.1954E-05" />
    </inertial>
    <visual>
      <origin
        xyz="0 0 0"
        rpy="0 0 0" />
      <geometry>
        <mesh
          filename="package://Snakebot/meshes/base_link.STL" />
      </geometry>
      <material
        name="">
        <color
          rgba="0.75294 0.75294 0.75294 1" />
      </material>
    </visual>
    <collision>
      <origin
        xyz="0 0 0"
        rpy="0 0 0" />
      <geometry>
        <mesh
          filename="package://Snakebot/meshes/base_link.STL" />
      </geometry>
    </collision>
  </link>
  <link
    name="chintu_1">
    <inertial>
      <origin
        xyz="5.2368E-08 0.0059135 0.00028384"
        rpy="0 0 0" />
      <mass
        value="0.0037139" />
      <inertia
        ixx="1.5739E-07"
        ixy="-3.2385E-21"
        ixz="-1.4468E-11"
        iyy="2.6234E-07"
        iyz="-4.8677E-13"
        izz="1.5609E-07" />
    </inertial>
    <visual>
      <origin
        xyz="0 0 0"
        rpy="0 0 0" />
      <geometry>
        <mesh
          filename="package://Snakebot/meshes/chintu_1.STL" />
      </geometry>
      <material
        name="">
        <color
          rgba="0.62745 0.62745 0.62745 1" />
      </material>
    </visual>
    <collision>
      <origin
        xyz="0 0 0"
        rpy="0 0 0" />
      <geometry>
        <mesh
          filename="package://Snakebot/meshes/chintu_1.STL" />
      </geometry>
    </collision>
  </link>
  <joint
    name="chintu_1_joint"
    type="continuous">
    <origin
      xyz="0.04 -0.017 -1.4731E-05"
      rpy="1.5708 -1.5708 0" />
    <parent
      link="base_link" />
    <child
      link="chintu_1" />
    <axis
      xyz="0 -1 0" />
  </joint>
  <link
    name="danda_1">
    <inertial>
      <origin
        xyz="-0.035021 0.015811 0.027514"
        rpy="0 0 0" />
      <mass
        value="0.012018" />
      <inertia
        ixx="5.772E-06"
        ixy="-3.9999E-09"
        ixz="5.3936E-06"
        iyy="1.2891E-05"
        iyz="3.3649E-09"
        izz="1.198E-05" />
    </inertial>
    <visual>
      <origin
        xyz="0 0 0"
        rpy="0 0 0" />
      <geometry>
        <mesh
          filename="package://Snakebot/meshes/danda_1.STL" />
      </geometry>
      <material
        name="">
        <color
          rgba="0.62745 0.62745 0.62745 1" />
      </material>
    </visual>
    <collision>
      <origin
        xyz="0 0 0"
        rpy="0 0 0" />
      <geometry>
        <mesh
          filename="package://Snakebot/meshes/danda_1.STL" />
      </geometry>
    </collision>
  </link>
  <joint
    name="danda_1_joint"
    type="continuous">
    <origin
      xyz="0 0.005 0.0125"
      rpy="0 0 -1.5708" />
    <parent
      link="chintu_1" />
    <child
      link="danda_1" />
    <axis
      xyz="0 -1 0.00018414" />
  </joint>
  <link
    name="chintu_4">
    <inertial>
      <origin
        xyz="8.3751E-11 -2.236E-06 0.012143"
        rpy="0 0 0" />
      <mass
        value="0.0029582" />
      <inertia
        ixx="2.2252E-07"
        ixy="4.6416E-19"
        ixz="-6.0019E-16"
        iyy="1.3682E-07"
        iyz="2.4255E-13"
        izz="1.355E-07" />
    </inertial>
    <visual>
      <origin
        xyz="0 0 0"
        rpy="0 0 0" />
      <geometry>
        <mesh
          filename="package://Snakebot/meshes/chintu_4.STL" />
      </geometry>
      <material
        name="">
        <color
          rgba="0.62745 0.62745 0.62745 1" />
      </material>
    </visual>
    <collision>
      <origin
        xyz="0 0 0"
        rpy="0 0 0" />
      <geometry>
        <mesh
          filename="package://Snakebot/meshes/chintu_4.STL" />
      </geometry>
    </collision>
  </link>
  <joint
    name="chintu_4_joint"
    type="continuous">
    <origin
      xyz="-0.07 1.0128E-05 0.055"
      rpy="0 0 3.1416" />
    <parent
      link="danda_1" />
    <child
      link="chintu_4" />
    <axis
      xyz="0 -1 -0.00018414" />
  </joint>
  <link
    name="top_base">
    <inertial>
      <origin
        xyz="-0.0010694 0.043151 0.0083727"
        rpy="0 0 0" />
      <mass
        value="0.10045" />
      <inertia
        ixx="5.7303E-05"
        ixy="3.2599E-07"
        ixz="3.4607E-07"
        iyy="5.1954E-05"
        iyz="1.0696E-07"
        izz="0.00010495" />
    </inertial>
    <visual>
      <origin
        xyz="0 0 0"
        rpy="0 0 0" />
      <geometry>
        <mesh
          filename="package://Snakebot/meshes/top_base.STL" />
      </geometry>
      <material
        name="">
        <color
          rgba="0.62745 0.62745 0.62745 1" />
      </material>
    </visual>
    <collision>
      <origin
        xyz="0 0 0"
        rpy="0 0 0" />
      <geometry>
        <mesh
          filename="package://Snakebot/meshes/top_base.STL" />
      </geometry>
    </collision>
  </link>
  <joint
    name="top_base_joint"
    type="continuous">
    <origin
      xyz="0.005 0 0.0125"
      rpy="0 -0.00018414 1.5708" />
    <parent
      link="chintu_4" />
    <child
      link="top_base" />
    <axis
      xyz="0 -1 0" />
  </joint>
  <link
    name="chintu_2">
    <inertial>
      <origin
        xyz="-6.5746E-08 0.005 0.00035704"
        rpy="0 0 0" />
      <mass
        value="0.0029582" />
      <inertia
        ixx="1.3682E-07"
        ixy="-3.2768E-21"
        ixz="2.4255E-13"
        iyy="2.2252E-07"
        iyz="-5.6439E-21"
        izz="1.355E-07" />
    </inertial>
    <visual>
      <origin
        xyz="0 0 0"
        rpy="0 0 0" />
      <geometry>
        <mesh
          filename="package://Snakebot/meshes/chintu_2.STL" />
      </geometry>
      <material
        name="">
        <color
          rgba="0.62745 0.62745 0.62745 1" />
      </material>
    </visual>
    <collision>
      <origin
        xyz="0 0 0"
        rpy="0 0 0" />
      <geometry>
        <mesh
          filename="package://Snakebot/meshes/chintu_2.STL" />
      </geometry>
    </collision>
  </link>
  <joint
    name="chintu_2_joint"
    type="continuous">
    <origin
      xyz="0 -0.017 -0.04"
      rpy="1.5708 0 0" />
    <parent
      link="base_link" />
    <child
      link="chintu_2" />
    <axis
      xyz="0 -1 0" />
  </joint>
  <link
    name="danda_2">
    <inertial>
      <origin
        xyz="-0.035021 0.015801 0.02752"
        rpy="0 0 0" />
      <mass
        value="0.012018" />
      <inertia
        ixx="5.772E-06"
        ixy="-5.9862E-09"
        ixz="5.3936E-06"
        iyy="1.289E-05"
        iyz="3.7001E-09"
        izz="1.198E-05" />
    </inertial>
    <visual>
      <origin
        xyz="0 0 0"
        rpy="0 0 0" />
      <geometry>
        <mesh
          filename="package://Snakebot/meshes/danda_2.STL" />
      </geometry>
      <material
        name="">
        <color
          rgba="0.62745 0.62745 0.62745 1" />
      </material>
    </visual>
    <collision>
      <origin
        xyz="0 0 0"
        rpy="0 0 0" />
      <geometry>
        <mesh
          filename="package://Snakebot/meshes/danda_2.STL" />
      </geometry>
    </collision>
  </link>
  <joint
    name="danda_2_joint"
    type="continuous">
    <origin
      xyz="0 0.005 0.0125"
      rpy="0 0 -1.5708" />
    <parent
      link="chintu_2" />
    <child
      link="danda_2" />
    <axis
      xyz="0 -1 -0.00018414" />
  </joint>
  <link
    name="chintu_5">
    <inertial>
      <origin
        xyz="-4.7958E-13 2.236E-06 0.012143"
        rpy="0 0 0" />
      <mass
        value="0.0029582" />
      <inertia
        ixx="2.2252E-07"
        ixy="-2.7596E-21"
        ixz="3.4431E-18"
        iyy="1.3682E-07"
        iyz="-2.4255E-13"
        izz="1.355E-07" />
    </inertial>
    <visual>
      <origin
        xyz="0 0 0"
        rpy="0 0 0" />
      <geometry>
        <mesh
          filename="package://Snakebot/meshes/chintu_5.STL" />
      </geometry>
      <material
        name="">
        <color
          rgba="0.62745 0.62745 0.62745 1" />
      </material>
    </visual>
    <collision>
      <origin
        xyz="0 0 0"
        rpy="0 0 0" />
      <geometry>
        <mesh
          filename="package://Snakebot/meshes/chintu_5.STL" />
      </geometry>
    </collision>
  </link>
  <joint
    name="chintu_5_joint"
    type="continuous">
    <origin
      xyz="-0.07 -1.0128E-05 0.055"
      rpy="0 0 3.1416" />
    <parent
      link="danda_2" />
    <child
      link="chintu_5" />
    <axis
      xyz="0 -1 0.00018414" />
  </joint>
  <link
    name="chintu_3">
    <inertial>
      <origin
        xyz="0 0 0"
        rpy="0 0 0" />
      <mass
        value="0" />
      <inertia
        ixx="0"
        ixy="0"
        ixz="0"
        iyy="0"
        iyz="0"
        izz="0" />
    </inertial>
    <visual>
      <origin
        xyz="0 0 0"
        rpy="0 0 0" />
      <geometry>
        <mesh
          filename="package://Snakebot/meshes/chintu_3.STL" />
      </geometry>
      <material
        name="">
        <color
          rgba="1 1 1 1" />
      </material>
    </visual>
    <collision>
      <origin
        xyz="0 0 0"
        rpy="0 0 0" />
      <geometry>
        <mesh
          filename="package://Snakebot/meshes/chintu_3.STL" />
      </geometry>
    </collision>
  </link>
  <joint
    name="chintu_3_joint"
    type="continuous">
    <origin
      xyz="-0.035355 -0.017 0.035355"
      rpy="-1.5708 0.7854 3.1416" />
    <parent
      link="base_link" />
    <child
      link="chintu_3" />
    <axis
      xyz="0 -1 0" />
  </joint>
  <link
    name="support_danda">
    <inertial>
      <origin
        xyz="-0.045001 0.021828 0.0275"
        rpy="0 0 0" />
      <mass
        value="0.014448" />
      <inertia
        ixx="8.1921E-06"
        ixy="-1.4932E-10"
        ixz="7.7942E-06"
        iyy="2.1824E-05"
        iyz="5.249E-11"
        izz="2.2679E-05" />
    </inertial>
    <visual>
      <origin
        xyz="0 0 0"
        rpy="0 0 0" />
      <geometry>
        <mesh
          filename="package://Snakebot/meshes/support_danda.STL" />
      </geometry>
      <material
        name="">
        <color
          rgba="0.62745 0.62745 0.62745 1" />
      </material>
    </visual>
    <collision>
      <origin
        xyz="0 0 0"
        rpy="0 0 0" />
      <geometry>
        <mesh
          filename="package://Snakebot/meshes/support_danda.STL" />
      </geometry>
    </collision>
  </link>
  <joint
    name="support_danda_joint"
    type="continuous">
    <origin
      xyz="0 0.005 0.0125"
      rpy="0 0 -1.5708" />
    <parent
      link="chintu_3" />
    <child
      link="support_danda" />
    <axis
      xyz="0 -1 0" />
  </joint>
  <link
    name="chintu_6">
    <inertial>
      <origin
        xyz="-1.1844E-10 -3.7793E-13 0.012143"
        rpy="0 0 0" />
      <mass
        value="0.0029582" />
      <inertia
        ixx="2.2252E-07"
        ixy="1.3539E-18"
        ixz="8.488E-16"
        iyy="1.3682E-07"
        iyz="3.6315E-20"
        izz="1.355E-07" />
    </inertial>
    <visual>
      <origin
        xyz="0 0 0"
        rpy="0 0 0" />
      <geometry>
        <mesh
          filename="package://Snakebot/meshes/chintu_6.STL" />
      </geometry>
      <material
        name="">
        <color
          rgba="0.62745 0.62745 0.62745 1" />
      </material>
    </visual>
    <collision>
      <origin
        xyz="0 0 0"
        rpy="0 0 0" />
      <geometry>
        <mesh
          filename="package://Snakebot/meshes/chintu_6.STL" />
      </geometry>
    </collision>
  </link>
  <joint
    name="chintu_6_joint"
    type="continuous">
    <origin
      xyz="-0.09 0 0.055"
      rpy="0 0 3.1416" />
    <parent
      link="support_danda" />
    <child
      link="chintu_6" />
    <axis
      xyz="0 -1 0" />
  </joint>
</robot>