<?xml version="1.0"?>
<robot name="snake_robot">

  <material name="blue">
    <color rgba="0 0 0.8 1"/>
  </material>

  <link name="base_link">
    <visual>
        <origin xyz="0.2 0 0" rpy="0 0 0"/>

      <geometry>
        <mesh filename="package://snake_bot/meshes/snake_module.stl" scale="0.01 0.01 0.01"/>
      </geometry>
      <material name="blue"/>
    </visual>
    <collision>
      <geometry>
        <mesh filename="package://snake_bot/meshes/snake_module.stl" scale="0.01 0.01 0.01"/>
      </geometry>
    </collision>
    <inertial>
      <mass value="1"/>
      <inertia ixx="0.000833" ixy="0.0" ixz="0.0" iyy="0.000833" iyz="0.0" izz="0.000833"/>
    </inertial>
  </link>

  <joint name="joint1" type="revolute">
    <parent link="base_link"/>
    <child link="segment1"/>
    <origin xyz="0 -1.1 0" rpy="0 0 0"/>
    <axis xyz="0 0 1"/>
    <limit lower="-1.57" upper="1.57" effort="100" velocity="1"/>
  </joint>

  <link name="segment1">
    <visual>
     <origin xyz="0 -0.56 0" rpy="0 0 0"/>
      <geometry>
        <mesh filename="package://snake_bot/meshes/snake_module.stl" scale="0.01 0.01 0.01"/>
      </geometry>
      <material name="blue"/>
    </visual>
    <collision>
      <geometry>
        <mesh filename="package://snake_bot/meshes/snake_module.stl" scale="0.01 0.01 0.01"/>
      </geometry>
    </collision>
    <inertial>
      <mass value="1"/>
      <inertia ixx="0.000833" ixy="0.0" ixz="0.0" iyy="0.000833" iyz="0.0" izz="0.000833"/>
    </inertial>
  </link>

  <joint name="joint2" type="revolute">
    <parent link="segment1"/>
    <child link="segment2"/>
    <origin xyz="0 -1.1 0" rpy="0 0 0"/>
    <axis xyz="0 0 1"/>
    <limit lower="-1.57" upper="1.57" effort="100" velocity="1"/>
  </joint>

  <link name="segment2">
    <visual>
      <geometry>
        <mesh filename="package://snake_bot/meshes/snake_module.stl" scale="0.01 0.01 0.01"/>
      </geometry>
      <material name="blue"/>
    </visual>
    <collision>
      <geometry>
        <mesh filename="package://snake_bot/meshes/snake_module.stl" scale="0.01 0.01 0.01"/>
      </geometry>
    </collision>
    <inertial>
      <mass value="1"/>
      <inertia ixx="0.000833" ixy="0.0" ixz="0.0" iyy="0.000833" iyz="0.0" izz="0.000833"/>
    </inertial>
  </link>

  <joint name="joint3" type="revolute">
    <parent link="segment2"/>
    <child link="segment3"/>
<origin xyz="0 -1.1 0" rpy="0 0 0"/>    <axis xyz="0 0 1"/>
    <limit lower="-1.57" upper="1.57" effort="100" velocity="1"/>
  </joint>

  <link name="segment3">
    <visual>
      <geometry>
        <mesh filename="package://snake_bot/meshes/snake_module.stl" scale="0.01 0.01 0.01"/>
      </geometry>
      <material name="blue"/>
    </visual>
    <collision>
      <geometry>
        <mesh filename="package://snake_bot/meshes/snake_module.stl" scale="0.01 0.01 0.01"/>
      </geometry>
    </collision>
    <inertial>
      <mass value="1"/>
      <inertia ixx="0.000833" ixy="0.0" ixz="0.0" iyy="0.000833" iyz="0.0" izz="0.000833"/>
    </inertial>
  </link>

  <joint name="joint4" type="revolute">
    <parent link="segment3"/>
    <child link="segment4"/>
<origin xyz="0 -1.1 0" rpy="0 0 0"/>    <axis xyz="0 0 1"/>
    <limit lower="-1.57" upper="1.57" effort="100" velocity="1"/>
  </joint>

  <link name="segment4">
    <visual>
      <geometry>
        <mesh filename="package://snake_bot/meshes/snake_module.stl" scale="0.01 0.01 0.01"/>
      </geometry>
      <material name="blue"/>
    </visual>
    <collision>
      <geometry>
        <mesh filename="package://snake_bot/meshes/snake_module.stl" scale="0.01 0.01 0.01"/>
      </geometry>
    </collision>
    <inertial>
      <mass value="1"/>
      <inertia ixx="0.000833" ixy="0.0" ixz="0.0" iyy="0.000833" iyz="0.0" izz="0.000833"/>
    </inertial>
  </link>

  <joint name="joint5" type="revolute">
    <parent link="segment4"/>
    <child link="segment5"/>
<origin xyz="0 -1.1 0" rpy="0 0 0"/>    <axis xyz="0 0 1"/>
    <limit lower="-1.57" upper="1.57" effort="100" velocity="1"/>
  </joint>

  <link name="segment5">
    <visual>
      <geometry>
        <mesh filename="package://snake_bot/meshes/snake_module.stl" scale="0.01 0.01 0.01"/>
      </geometry>
      <material name="blue"/>
    </visual>
    <collision>
      <geometry>
        <mesh filename="package://snake_bot/meshes/snake_module.stl" scale="0.01 0.01 0.01"/>
      </geometry>
    </collision>
    <inertial>
      <mass value="1"/>
      <inertia ixx="0.000833" ixy="0.0" ixz="0.0" iyy="0.000833" iyz="0.0" izz="0.000833"/>
    </inertial>
  </link>

  <joint name="joint6" type="revolute">
    <parent link="segment5"/>
    <child link="segment6"/>
<origin xyz="0 -1.1 0" rpy="0 0 0"/>    <axis xyz="0 0 1"/>
    <limit lower="-1.57" upper="1.57" effort="100" velocity="1"/>
  </joint>

  <link name="segment6">
    <visual>
      <geometry>
        <mesh filename="package://snake_bot/meshes/snake_module.stl" scale="0.01 0.01 0.01"/>
      </geometry>
      <material name="blue"/>
    </visual>
    <collision>
      <geometry>
        <mesh filename="package://snake_bot/meshes/snake_module.stl" scale="0.01 0.01 0.01"/>
      </geometry>
    </collision>
    <inertial>
      <mass value="1"/>
      <inertia ixx="0.000833" ixy="0.0" ixz="0.0" iyy="0.000833" iyz="0.0" izz="0.000833"/>
    </inertial>
  </link>

</robot>
